<?xml version="1.0"?>
<robot name="new_mobile_robot">

  <!-- ================= BASIC DIMENSIONS ================= -->
  <!-- wheel radius = 0.0674 -->
  <!-- wheel thickness = 0.055 -->
  <!-- body size = 0.40 x 0.28 x 0.12 -->

  <link name="base_footprint"/>

  <joint name="base_footprint_joint" type="fixed">
    <parent link="base_footprint"/>
    <child link="base_link"/>
    <origin xyz="0 0 0.1274" rpy="0 0 0"/>
  </joint>

  <!-- ================= ROBOT BODY ================= -->
  <link name="base_link">
    <inertial>
      <origin xyz="0 0 -0.04" rpy="0 0 0"/>
      <mass value="15.0"/>
      <inertia ixx="0.10" ixy="0" ixz="0"
               iyy="0.20" iyz="0" izz="0.25"/>
    </inertial>

    <visual name="base_visual">
      <origin xyz="0 0 0" rpy="0 0 0"/>
      <geometry>
        <box size="0.40 0.28 0.12"/>
      </geometry>
      <material name="blue_body">
        <color rgba="0.0 0.25 1.0 1.0"/>
      </material>
    </visual>

    <collision name="base_collision">
      <origin xyz="0 0 0" rpy="0 0 0"/>
      <geometry>
        <box size="0.40 0.28 0.12"/>
      </geometry>
    </collision>
  </link>

  <!-- ================= LEFT FRONT WHEEL ================= -->
  <link name="left_front_wheel">
    <inertial>
      <origin xyz="0 0 0" rpy="0 0 0"/>
      <mass value="0.8"/>
      <inertia ixx="0.001" ixy="0" ixz="0"
               iyy="0.001" iyz="0" izz="0.001"/>
    </inertial>

    <visual name="left_front_wheel_visual">
      <origin xyz="0 0 0" rpy="1.5708 0 0"/>
      <geometry>
        <cylinder radius="0.0674" length="0.055"/>
      </geometry>
      <material name="wheel_black">
        <color rgba="0.01 0.01 0.01 1"/>
      </material>
    </visual>

    <collision name="left_front_wheel_collision">
      <origin xyz="0 0 0" rpy="1.5708 0 0"/>
      <geometry>
        <cylinder radius="0.0674" length="0.055"/>
      </geometry>
    </collision>
  </link>

  <joint name="left_front_joint" type="continuous">
    <parent link="base_link"/>
    <child link="left_front_wheel"/>
    <origin xyz="0.14 0.17 -0.06" rpy="0 0 0"/>
    <axis xyz="0 1 0"/>
    <dynamics damping="0.1" friction="0.1"/>
  </joint>

  <!-- ================= RIGHT FRONT WHEEL ================= -->
  <link name="right_front_wheel">
    <inertial>
      <origin xyz="0 0 0" rpy="0 0 0"/>
      <mass value="0.8"/>
      <inertia ixx="0.001" ixy="0" ixz="0"
               iyy="0.001" iyz="0" izz="0.001"/>
    </inertial>

    <visual name="right_front_wheel_visual">
      <origin xyz="0 0 0" rpy="1.5708 0 0"/>
      <geometry>
        <cylinder radius="0.0674" length="0.055"/>
      </geometry>
      <material name="wheel_black">
        <color rgba="0.01 0.01 0.01 1"/>
      </material>
    </visual>

    <collision name="right_front_wheel_collision">
      <origin xyz="0 0 0" rpy="1.5708 0 0"/>
      <geometry>
        <cylinder radius="0.0674" length="0.055"/>
      </geometry>
    </collision>
  </link>

  <joint name="right_front_joint" type="continuous">
    <parent link="base_link"/>
    <child link="right_front_wheel"/>
    <origin xyz="0.14 -0.17 -0.06" rpy="0 0 0"/>
    <axis xyz="0 1 0"/>
    <dynamics damping="0.1" friction="0.1"/>
  </joint>

  <!-- ================= LEFT BACK WHEEL ================= -->
  <link name="left_back_wheel">
    <inertial>
      <origin xyz="0 0 0" rpy="0 0 0"/>
      <mass value="0.8"/>
      <inertia ixx="0.001" ixy="0" ixz="0"
               iyy="0.001" iyz="0" izz="0.001"/>
    </inertial>

    <visual name="left_back_wheel_visual">
      <origin xyz="0 0 0" rpy="1.5708 0 0"/>
      <geometry>
        <cylinder radius="0.0674" length="0.055"/>
      </geometry>
      <material name="wheel_black">
        <color rgba="0.01 0.01 0.01 1"/>
      </material>
    </visual>

    <collision name="left_back_wheel_collision">
      <origin xyz="0 0 0" rpy="1.5708 0 0"/>
      <geometry>
        <cylinder radius="0.0674" length="0.055"/>
      </geometry>
    </collision>
  </link>

  <joint name="left_back_joint" type="continuous">
    <parent link="base_link"/>
    <child link="left_back_wheel"/>
    <origin xyz="-0.14 0.17 -0.06" rpy="0 0 0"/>
    <axis xyz="0 1 0"/>
    <dynamics damping="0.1" friction="0.1"/>
  </joint>

  <!-- ================= RIGHT BACK WHEEL ================= -->
  <link name="right_back_wheel">
    <inertial>
      <origin xyz="0 0 0" rpy="0 0 0"/>
      <mass value="0.8"/>
      <inertia ixx="0.001" ixy="0" ixz="0"
               iyy="0.001" iyz="0" izz="0.001"/>
    </inertial>

    <visual name="right_back_wheel_visual">
      <origin xyz="0 0 0" rpy="1.5708 0 0"/>
      <geometry>
        <cylinder radius="0.0674" length="0.055"/>
      </geometry>
      <material name="wheel_black">
        <color rgba="0.01 0.01 0.01 1"/>
      </material>
    </visual>

    <collision name="right_back_wheel_collision">
      <origin xyz="0 0 0" rpy="1.5708 0 0"/>
      <geometry>
        <cylinder radius="0.0674" length="0.055"/>
      </geometry>
    </collision>
  </link>

  <joint name="right_back_joint" type="continuous">
    <parent link="base_link"/>
    <child link="right_back_wheel"/>
    <origin xyz="-0.14 -0.17 -0.06" rpy="0 0 0"/>
    <axis xyz="0 1 0"/>
    <dynamics damping="0.1" friction="0.1"/>
  </joint>

  <!-- ================= LIDAR ================= -->
  <link name="lidar_link">
    <inertial>
      <origin xyz="0 0 0" rpy="0 0 0"/>
      <mass value="0.1"/>
      <inertia ixx="0.0001" ixy="0" ixz="0"
               iyy="0.0001" iyz="0" izz="0.0001"/>
    </inertial>

    <visual name="lidar_visual">
      <origin xyz="0 0 0" rpy="0 0 0"/>
      <geometry>
        <cylinder radius="0.04" length="0.04"/>
      </geometry>
      <material name="lidar_gray">
        <color rgba="0.7 0.7 0.7 1"/>
      </material>
    </visual>

    <collision name="lidar_collision">
      <origin xyz="0 0 0" rpy="0 0 0"/>
      <geometry>
        <cylinder radius="0.04" length="0.04"/>
      </geometry>
    </collision>
  </link>

  <joint name="lidar_joint" type="fixed">
    <parent link="base_link"/>
    <child link="lidar_link"/>
    <origin xyz="0 0 0.10" rpy="0 0 0"/>
  </joint>

  <!-- ================= GAZEBO COLORS / FRICTION ================= -->
  <gazebo reference="base_link">
    <material>Gazebo/Blue</material>
  </gazebo>

  <gazebo reference="left_front_wheel">
    <material>Gazebo/Black</material>
    <mu1>0.8</mu1>
    <mu2>0.8</mu2>
  </gazebo>

  <gazebo reference="right_front_wheel">
    <material>Gazebo/Black</material>
    <mu1>0.8</mu1>
    <mu2>0.8</mu2>
  </gazebo>

  <gazebo reference="left_back_wheel">
    <material>Gazebo/Black</material>
    <mu1>0.8</mu1>
    <mu2>0.8</mu2>
  </gazebo>

  <gazebo reference="right_back_wheel">
    <material>Gazebo/Black</material>
    <mu1>0.8</mu1>
    <mu2>0.8</mu2>
  </gazebo>

  <!-- ================= LIDAR SENSOR ================= -->
  <gazebo reference="lidar_link">
    <material>Gazebo/Grey</material>

    <sensor name="lidar" type="ray">
      <always_on>true</always_on>
      <visualize>false</visualize>
      <update_rate>10</update_rate>

      <ray>
        <scan>
          <horizontal>
            <samples>360</samples>
            <resolution>1</resolution>
            <min_angle>-3.14159</min_angle>
            <max_angle>3.14159</max_angle>
          </horizontal>
        </scan>

        <range>
          <min>0.15</min>
          <max>10.0</max>
          <resolution>0.01</resolution>
        </range>

        <noise>
          <type>gaussian</type>
          <mean>0.0</mean>
          <stddev>0.01</stddev>
        </noise>
      </ray>

      <plugin name="gazebo_ros_lidar" filename="libgazebo_ros_ray_sensor.so">
        <ros>
          <remapping>~/out:=scan</remapping>
        </ros>
        <output_type>sensor_msgs/LaserScan</output_type>
        <frame_name>lidar_link</frame_name>
      </plugin>
    </sensor>
  </gazebo>

  <!-- ================= DIFF DRIVE ================= -->
  <gazebo>
    <plugin name="diff_drive" filename="libgazebo_ros_diff_drive.so">
      <ros>
        <namespace>/</namespace>
        <remapping>cmd_vel:=cmd_vel</remapping>
        <remapping>odom:=odom</remapping>
      </ros>

      <update_rate>50</update_rate>

      <left_joint>left_back_joint</left_joint>
      <right_joint>right_back_joint</right_joint>

      <wheel_separation>0.34</wheel_separation>
      <wheel_diameter>0.1348</wheel_diameter>

      <max_wheel_torque>20.0</max_wheel_torque>
      <max_wheel_acceleration>2.0</max_wheel_acceleration>

      <publish_odom>true</publish_odom>
      <publish_odom_tf>true</publish_odom_tf>
      <publish_wheel_tf>true</publish_wheel_tf>

      <odometry_frame>odom</odometry_frame>
      <robot_base_frame>base_footprint</robot_base_frame>
    </plugin>
  </gazebo>

</robot>
